Workbook

Sheet Test Cases
A1: Test Case No | B1: Module | C1: Page / URL | D1: Test Type | E1: Priority | F1: Preconditions | G1: Test Case (Steps) | H1: Expected Result | I1: Output (Actual Result) | J1: Status | K1: Browser / Device | L1: Tested By | M1: Tested On | N1: Defect / Bug ID | O1: Remarks
A2: TC-HOME-001 | B2: Home | C2: / | D2: Functional | E2: High | F2: Signed out | G2: Open the site root | H2: Home page loads with hero, nav bar, feature sections, pricing teaser and footer; no console errors; tab title is set | I2: Working | J2: Pass | K2: Microsoft edge | L2: Sabuja | M2: 46063
A3: TC-HOME-002 | B3: Home | C3: / | D3: Functional | E3: High | F3: Signed out | G3: Click each nav item (Features, Solutions, Pricing, About, Contact, Help, Developers) | H3: Each navigates to the correct page; active item is highlighted | I3: All working but the sub nav links are not highlighted. | J3: Pass | K3: Microsoft edge | L3: Sabuja | M3: 46063
A4: TC-HOME-003 | B4: Home | C4: / | D4: Functional | E4: High | F4: Signed out | G4: Click 'Log in' and 'Register / Get started' buttons in header and in hero | H4: Go to /login and /register respectively | I4: Can able to go to login/ Signup pages | J4: Pass | K4: Microsoft edge | L4: Sabuja | M4: 46063
A5: TC-HOME-004 | B5: Home | C5: / | D5: Functional | E5: Medium | F5: Signed out | G5: Click every CTA button in each home section and the bottom CTA band | H5: Every CTA goes to a valid page (no 404 / dead link) | I5: Every CTA goes to valid pages | J5: Pass | K5: Microsoft edge | L5: Sabuja | M5: 46063
A6: TC-HOME-005 | B6: Home | C6: / | D6: Functional | E6: Medium | F6: Signed out | G6: Scroll the full page and click each in-page anchor / section link | H6: Smooth scroll to the right section; no jump to wrong place | I6: No anchors found | J6: Skipped | K6: Microsoft edge | L6: Sabuja | M6: 46063
A7: TC-HOME-006 | B7: Home | C7: / | D7: Functional | E7: Medium | F7: Signed out | G7: Click every footer link (product, company, legal, social) | H7: All links work; external links open in a new tab; legal links open Privacy, Terms, Refund policy | I7: All links are properly working | J7: Pass | K7: Microsoft edge | L7: Sabuja | M7: 46063
A8: TC-HOME-007 | B8: Home | C8: / | D8: Functional | E8: Medium | F8: Signed in | G8: Open / while signed in | H8: Signed-in user sees the app dashboard (or onboarding / plan selection if incomplete), not the marketing page | I8: Opening Dashboard | J8: Pass | K8: Microsoft edge | L8: Sabuja | M8: 46063
A9: TC-HOME-008 | B9: Home | C9: / | D9: UI / Layout | E9: Low | F9: Signed out | G9: Toggle dark / light theme (if theme toggle present) | H9: Theme switches; text contrast stays readable; choice persists on refresh | I9: No theme button found | J9: Skipped | K9: Microsoft edge | L9: Sabuja | M9: 46063
A10: TC-HOME-009 | B10: Home | C10: / | D10: Responsive | E10: High | F10: Signed out | G10: View at 375px, 768px, 1280px, 1920px widths | H10: No horizontal scroll; hamburger menu appears on mobile; images and cards reflow | I10: Working fine in responsive | J10: Pass | K10: Microsoft edge | L10: Sabuja | M10: 46063
A11: TC-HOME-010 | B11: Home | C11: / | D11: Responsive | E11: Medium | F11: Signed out | G11: On mobile open the hamburger menu, tap a link, then tap outside | H11: Menu opens, link navigates and menu closes; no scroll lock left behind | I11: Working fine in responsive | J11: Pass | K11: Microsoft edge | L11: Sabuja | M11: 46063
A12: TC-HOME-011 | B12: Home | C12: / | D12: Performance | E12: Medium | F12: Signed out | G12: Hard refresh on a slow 3G throttle | H12: Page shows content progressively; images lazy-load; no layout shift on load | I12: Content becomes visible only after the page has completely loaded. No images are present on the page. No layout shift was observed. | J12: Pass | K12: Microsoft edge | L12: Sabuja | M12: 46063
A13: TC-HOME-012 | B13: Home | C13: / | D13: SEO | E13: Low | F13: Signed out | G13: View page source / inspect head | H13: Title, meta description, canonical, Open Graph tags present | I13: Title, meta description and Open Graph tags are present in the page source. Canonical link tag is missing. | J13: Pass | K13: Microsoft edge | L13: Sabuja | M13: 46063
... A34: TC-LOGIN-005 | B34: Login | C34: /login | D34: Validation | E34: High | F34: Signed out | G34: Leave both fields empty and click Log in | H34: Browser/required validation blocks submit on email | I34: Browser/required validation blocks submit on email | J34: Pass | K34: Microsoft edge | L34: Sabuja | M34: 46063
A35: TC-LOGIN-006 | B35: Login | C35: /login | D35: Validation | E35: Medium | F35: Signed out | G35: Enter email 'abc' / 'abc@' / 'abc@x' and submit | H35: Invalid email rejected | I35: [ { "validation": "email", "code": "invalid_string", "message": "Invalid email", "path": [ "email" ] } ] | J35: Pass | K35: Microsoft edge | L35: Sabuja | M35: 46063 | O35: Should show message not error json
A36: TC-LOGIN-007 | B36: Login | C36: /login | D36: Validation | E36: Medium | F36: Signed out | G36: Enter password with fewer than 8 characters | H36: Blocked with min-length validation | I36: Blocked with min-length validation | J36: Pass | K36: Microsoft edge | L36: Sabuja | M36: 46063
A37: TC-LOGIN-008 | B37: Login | C37: /login | D37: Validation | E37: Medium | F37: Signed out | G37: Enter email with leading/trailing spaces and different case, e.g. ' User@Mail.com ' | H37: Login works (trimmed and case-insensitive) or a clear message | I37: Invalid email or password | J37: Pass | K37: Microsoft edge | L37: Sabuja | M37: 46063
A38: TC-LOGIN-009 | B38: Login | C38: /login | D38: Functional | E38: Medium | F38: Signed out | G38: Click the eye icon in the password box | H38: Password toggles visible / hidden; focus stays in field | I38: Focus not staying | J38: Pass | K38: Microsoft edge | L38: Sabuja | M38: 46063
A39: TC-LOGIN-010 | B39: Login | C39: /login | D39: Functional | E39: Medium | F39: Signed out | G39: Press Enter in the password field | H39: Form submits (same as clicking Log in) | I39: Working | J39: Pass | K39: Microsoft edge | L39: Sabuja | M39: 46063
A40: TC-LOGIN-011 | B40: Login | C40: /login | D40: Functional | E40: Medium | F40: Signed out | G40: Double-click Log in rapidly | H40: Only one request; button disabled while pending | I40: Bug: rapid click opening http://localhost:5173/features page | J40: Pass | K40: Microsoft edge | L40: Sabuja | M40: 46063
A41: TC-LOGIN-012 | B41: Login | C41: /login | D41: Functional | E41: Medium | F41: Signed out | G41: Click 'Email me a sign-in link' with email empty | H41: Error: 'Enter your email address first, then we'll send you a sign-in link.' | I41: Enter your email address first, then we'll send you a sign-in link. | J41: Pass | K41: Microsoft edge | L41: Sabuja | M41: 46063
A42: TC-LOGIN-013 | B42: Login | C42: /login | D42: Functional | E42: High | F42: Account exists | G42: Enter email and click 'Email me a sign-in link'; complete bot check | H42: Bot check (Turnstile) modal appears; after passing, banner 'We sent a sign-in link to <email>'; button shows 'Resend link in 60s' countdown | I42: We sent a sign-in link to illusodesigns@gmail.com. Open it on this device to log in. | J42: Pass | K42: Microsoft edge | L42: Sabuja | M42: 46063
A43: TC-LOGIN-014 | B43: Login | C43: /login | D43: Functional | E43: Medium | F43: Signed out | G43: Close the bot-check modal without completing it | H43: Modal closes; no email sent; page still usable; can retry | I43: All four verification criteria passed. | J43: Pass | K43: Microsoft edge | L43: Sabuja | M43: 46063
A44: TC-LOGIN-015 | B44: Login | C44: /login | D44: Functional | E44: Medium | F44: Signed out | G44: During the 60s cooldown try clicking the link button | H44: Button disabled; counts down; re-enabled at 0 | I44: Button disabled; counts down; re-enabled at 0 | J44: Pass | K44: Microsoft edge | L44: Sabuja | M44: 46063
A45: TC-LOGIN-016 | B45: Login | C45: /login | D45: Functional | E45: Medium | F45: Signed out | G45: Request a link for an email not registered | H45: Behaviour is safe (creates account flow or generic message); no crash | I45: No mail was actually sending to login | J45: Pass | K45: Microsoft edge | L45: Sabuja | M45: 46063
A46: TC-LOGIN-017 | B46: Login | C46: /login | D46: Security | E46: High | F46: Signed out | G46: Request sign-in link many times quickly (spam) | H46: Rate limiting kicks in with a friendly message | I46: Filed to rate limiting and opens multiple time | J46: Pass | K46: Microsoft edge | L46: Sabuja | M46: 46063
A47: TC-LOGIN-018 | B47: Login | C47: /login | D47: Security | E47: High | F47: Signed out | G47: Try SQL / script payloads in email and password e.g. ' OR 1=1 -- and <script>alert(1)</script> | H47: Rejected or treated as plain text; no script executes; no 500 error | I47: In both cases: Invalid email or password | J47: Pass | K47: Microsoft edge | L47: Sabuja | M47: 46063
... A55: TC-LOGIN-026 | B55: Login | C55: /login | D55: Functional | E55: Low | F55: Signed out | G55: Click the logo (left panel / mobile logo) | H55: Goes to home page | I55: Redirected to home page | J55: Pass | K55: Microsoft edge | L55: Sabuja | M55: 46063
A56: TC-LOGIN-027 | B56: Login | C56: /login | D56: Functional | E56: Medium | F56: Browser password manager | G56: Save and auto-fill credentials | H56: Auto-fill works for email and password | J56: Not Run
A57: TC-LOGIN-028 | B57: Login | C57: /login | D57: UI / Layout | E57: Low | F57: Signed out | G57: Check left brand panel on desktop | H57: Panel visible on large screens; hidden on tablet/mobile with logo shown instead | J57: Pass
A58: TC-LOGIN-029 | B58: Login | C58: /login | D58: Responsive | E58: Medium | F58: Signed out | G58: Open at 320px / 375px width | H58: Form fully visible; no overflow; keyboard doesn't cover the Log in button | J58: Pass
A59: TC-LOGIN-030 | B59: Login | C59: /login | D59: Accessibility | E59: Low | F59: Signed out | G59: Use a screen reader / Tab through form | H59: Labels read correctly; errors announced (role=alert) | J59: Not Run
A60: TC-LOGIN-031 | B60: Login | C60: /login | D60: Functional | E60: Medium | F60: Suspended / disabled account | G60: Log in with a suspended or disabled account | H60: Clear error message; no access | J60: Not Run
A61: TC-LOGIN-032 | B61: Login | C61: /login | D61: Functional | E61: Low | F61: Signed out | G61: Check tab title | H61: Title reads 'Log in - Fintranzact' | J61: Not Run
A62: TC-REG-001 | B62: Register | C62: /register | D62: Functional | E62: High | F62: Signed out | G62: Open /register | H62: Fields: Username, Referral code (optional), Email, Password, Retype password; strength meter; Terms and Privacy links; 'Register' tab active | J62: Not Run
A63: TC-REG-002 | B63: Register | C63: /register | D63: Functional | E63: High | F63: Signed out | G63: Fill all fields with valid new data and click 'Create free account'; pass bot check | H63: Account created, button shows 'Creating your account...', lands on /auth/plan-selection, session active | J63: Not Run
A64: TC-REG-003 | B64: Register | C64: /register | D64: Validation | E64: High | F64: Signed out | G64: Submit with empty username | H64: Error 'Username is required' (or required validation) | J64: Not Run
A65: TC-REG-004 | B65: Register | C65: /register | D65: Validation | E65: Medium | F65: Signed out | G65: Username with only spaces | H65: Rejected as empty | J65: Not Run
A66: TC-REG-005 | B66: Register | C66: /register | D66: Validation | E66: Medium | F66: Signed out | G66: Very long username (200+ chars), special chars, emoji, unicode (Hindi / Gujarati) | H66: Handled gracefully: accepted or clear validation message; no crash | J66: Not Run
A67: TC-REG-006 | B67: Register | C67: /register | D67: Validation | E67: High | F67: Signed out | G67: Invalid emails: 'abc', 'a@b', 'a b@c.com', '@x.com' | H67: Rejected | J67: Not Run
...

Sheet Summary
A1: Module | B1: Total | C1: Pass | D1: Fail | E1: Blocked | F1: Skipped | G1: Not Run | H1: % Executed
A2: Home | B2: =COUNTIF('Test Cases'!B:B,A2) -> 12 | C2: =COUNTIFS('Test Cases'!B:B,$A2,'Test Cases'!J:J,"Pass") -> 10 | D2: =COUNTIFS('Test Cases'!B:B,$A2,'Test Cases'!J:J,"Fail") -> 0 | E2: =COUNTIFS('Test Cases'!B:B,$A2,'Test Cases'!J:J,"Blocked") -> 0 | F2: =COUNTIFS('Test Cases'!B:B,$A2,'Test Cases'!J:J,"Skipped") -> 2 | G2: =COUNTIFS('Test Cases'!B:B,$A2,'Test Cases'!J:J,"Not Run") -> 0 | H2: =IF(B2=0,0,(B2-G2)/B2) -> 1
A3: Global / Routing | B3: =COUNTIF('Test Cases'!B:B,A3) -> 16 | C3: =COUNTIFS('Test Cases'!B:B,$A3,'Test Cases'!J:J,"Pass") -> 15 | D3: =COUNTIFS('Test Cases'!B:B,$A3,'Test Cases'!J:J,"Fail") -> 0 | E3: =COUNTIFS('Test Cases'!B:B,$A3,'Test Cases'!J:J,"Blocked") -> 0 | F3: =COUNTIFS('Test Cases'!B:B,$A3,'Test Cases'!J:J,"Skipped") -> 1 | G3: =COUNTIFS('Test Cases'!B:B,$A3,'Test Cases'!J:J,"Not Run") -> 0 | H3: =IF(B3=0,0,(B3-G3)/B3) -> 1
A4: Login | B4: =COUNTIF('Test Cases'!B:B,A4) -> 32 | C4: =COUNTIFS('Test Cases'!B:B,$A4,'Test Cases'!J:J,"Pass") -> 26 | D4: =COUNTIFS('Test Cases'!B:B,$A4,'Test Cases'!J:J,"Fail") -> 2 | E4: =COUNTIFS('Test Cases'!B:B,$A4,'Test Cases'!J:J,"Blocked") -> 0 | F4: =COUNTIFS('Test Cases'!B:B,$A4,'Test Cases'!J:J,"Skipped") -> 0 | G4: =COUNTIFS('Test Cases'!B:B,$A4,'Test Cases'!J:J,"Not Run") -> 4 | H4: =IF(B4=0,0,(B4-G4)/B4) -> 0.875
A5: Register | B5: =COUNTIF('Test Cases'!B:B,A5) -> 31 | C5: =COUNTIFS('Test Cases'!B:B,$A5,'Test Cases'!J:J,"Pass") -> 0 | D5: =COUNTIFS('Test Cases'!B:B,$A5,'Test Cases'!J:J,"Fail") -> 0 | E5: =COUNTIFS('Test Cases'!B:B,$A5,'Test Cases'!J:J,"Blocked") -> 0 | F5: =COUNTIFS('Test Cases'!B:B,$A5,'Test Cases'!J:J,"Skipped") -> 0 | G5: =COUNTIFS('Test Cases'!B:B,$A5,'Test Cases'!J:J,"Not Run") -> 31 | H5: =IF(B5=0,0,(B5-G5)/B5) -> 0
A6: Sign-in link verification | B6: =COUNTIF('Test Cases'!B:B,A6) -> 11 | C6: =COUNTIFS('Test Cases'!B:B,$A6,'Test Cases'!J:J,"Pass") -> 0 | D6: =COUNTIFS('Test Cases'!B:B,$A6,'Test Cases'!J:J,"Fail") -> 0 | E6: =COUNTIFS('Test Cases'!B:B,$A6,'Test Cases'!J:J,"Blocked") -> 0 | F6: =COUNTIFS('Test Cases'!B:B,$A6,'Test Cases'!J:J,"Skipped") -> 0 | G6: =COUNTIFS('Test Cases'!B:B,$A6,'Test Cases'!J:J,"Not Run") -> 11 | H6: =IF(B6=0,0,(B6-G6)/B6) -> 0
A7: Complete profile | B7: =COUNTIF('Test Cases'!B:B,A7) -> 10 | C7: =COUNTIFS('Test Cases'!B:B,$A7,'Test Cases'!J:J,"Pass") -> 0 | D7: =COUNTIFS('Test Cases'!B:B,$A7,'Test Cases'!J:J,"Fail") -> 0 | E7: =COUNTIFS('Test Cases'!B:B,$A7,'Test Cases'!J:J,"Blocked") -> 0 | F7: =COUNTIFS('Test Cases'!B:B,$A7,'Test Cases'!J:J,"Skipped") -> 0 | G7: =COUNTIFS('Test Cases'!B:B,$A7,'Test Cases'!J:J,"Not Run") -> 10 | H7: =IF(B7=0,0,(B7-G7)/B7) -> 0
A8: Plan selection | B8: =COUNTIF('Test Cases'!B:B,A8) -> 9 | C8: =COUNTIFS('Test Cases'!B:B,$A8,'Test Cases'!J:J,"Pass") -> 0 | D8: =COUNTIFS('Test Cases'!B:B,$A8,'Test Cases'!J:J,"Fail") -> 0 | E8: =COUNTIFS('Test Cases'!B:B,$A8,'Test Cases'!J:J,"Blocked") -> 0 | F8: =COUNTIFS('Test Cases'!B:B,$A8,'Test Cases'!J:J,"Skipped") -> 0 | G8: =COUNTIFS('Test Cases'!B:B,$A8,'Test Cases'!J:J,"Not Run") -> 9 | H8: =IF(B8=0,0,(B8-G8)/B8) -> 0
A9: Onboarding & create business | B9: =COUNTIF('Test Cases'!B:B,A9) -> 6 | C9: =COUNTIFS('Test Cases'!B:B,$A9,'Test Cases'!J:J,"Pass") -> 0 | D9: =COUNTIFS('Test Cases'!B:B,$A9,'Test Cases'!J:J,"Fail") -> 0 | E9: =COUNTIFS('Test Cases'!B:B,$A9,'Test Cases'!J:J,"Blocked") -> 0 | F9: =COUNTIFS('Test Cases'!B:B,$A9,'Test Cases'!J:J,"Skipped") -> 0 | G9: =COUNTIFS('Test Cases'!B:B,$A9,'Test Cases'!J:J,"Not Run") -> 6 | H9: =IF(B9=0,0,(B9-G9)/B9) -> 0
A10: Team invitation | B10: =COUNTIF('Test Cases'!B:B,A10) -> 9 | C10: =COUNTIFS('Test Cases'!B:B,$A10,'Test Cases'!J:J,"Pass") -> 0 | D10: =COUNTIFS('Test Cases'!B:B,$A10,'Test Cases'!J:J,"Fail") -> 0 | E10: =COUNTIFS('Test Cases'!B:B,$A10,'Test Cases'!J:J,"Blocked") -> 0 | F10: =COUNTIFS('Test Cases'!B:B,$A10,'Test Cases'!J:J,"Skipped") -> 0 | G10: =COUNTIFS('Test Cases'!B:B,$A10,'Test Cases'!J:J,"Not Run") -> 9 | H10: =IF(B10=0,0,(B10-G10)/B10) -> 0
A11: Shared document link | B11: =COUNTIF('Test Cases'!B:B,A11) -> 24 | C11: =COUNTIFS('Test Cases'!B:B,$A11,'Test Cases'!J:J,"Pass") -> 0 | D11: =COUNTIFS('Test Cases'!B:B,$A11,'Test Cases'!J:J,"Fail") -> 0 | E11: =COUNTIFS('Test Cases'!B:B,$A11,'Test Cases'!J:J,"Blocked") -> 0 | F11: =COUNTIFS('Test Cases'!B:B,$A11,'Test Cases'!J:J,"Skipped") -> 0 | G11: =COUNTIFS('Test Cases'!B:B,$A11,'Test Cases'!J:J,"Not Run") -> 24 | H11: =IF(B11=0,0,(B11-G11)/B11) -> 0
A12: Pricing | B12: =COUNTIF('Test Cases'!B:B,A12) -> 9 | C12: =COUNTIFS('Test Cases'!B:B,$A12,'Test Cases'!J:J,"Pass") -> 0 | D12: =COUNTIFS('Test Cases'!B:B,$A12,'Test Cases'!J:J,"Fail") -> 0 | E12: =COUNTIFS('Test Cases'!B:B,$A12,'Test Cases'!J:J,"Blocked") -> 0 | F12: =COUNTIFS('Test Cases'!B:B,$A12,'Test Cases'!J:J,"Skipped") -> 0 | G12: =COUNTIFS('Test Cases'!B:B,$A12,'Test Cases'!J:J,"Not Run") -> 9 | H12: =IF(B12=0,0,(B12-G12)/B12) -> 0
A13: Features | B13: =COUNTIF('Test Cases'!B:B,A13) -> 8 | C13: =COUNTIFS('Test Cases'!B:B,$A13,'Test Cases'!J:J,"Pass") -> 0 | D13: =COUNTIFS('Test Cases'!B:B,$A13,'Test Cases'!J:J,"Fail") -> 0 | E13: =COUNTIFS('Test Cases'!B:B,$A13,'Test Cases'!J:J,"Blocked") -> 0 | F13: =COUNTIFS('Test Cases'!B:B,$A13,'Test Cases'!J:J,"Skipped") -> 0 | G13: =COUNTIFS('Test Cases'!B:B,$A13,'Test Cases'!J:J,"Not Run") -> 8 | H13: =IF(B13=0,0,(B13-G13)/B13) -> 0
... A26: System & infrastructure | B26: =COUNTIF('Test Cases'!B:B,A26) -> 8 | C26: =COUNTIFS('Test Cases'!B:B,$A26,'Test Cases'!J:J,"Pass") -> 0 | D26: =COUNTIFS('Test Cases'!B:B,$A26,'Test Cases'!J:J,"Fail") -> 0 | E26: =COUNTIFS('Test Cases'!B:B,$A26,'Test Cases'!J:J,"Blocked") -> 0 | F26: =COUNTIFS('Test Cases'!B:B,$A26,'Test Cases'!J:J,"Skipped") -> 0 | G26: =COUNTIFS('Test Cases'!B:B,$A26,'Test Cases'!J:J,"Not Run") -> 8 | H26: =IF(B26=0,0,(B26-G26)/B26) -> 0
A27: TOTAL | B27: =SUM(B2:B26) -> 275 | C27: =SUM(C2:C26) -> 51 | D27: =SUM(D2:D26) -> 2 | E27: =SUM(E2:E26) -> 0 | F27: =SUM(F2:F26) -> 3 | G27: =SUM(G2:G26) -> 219 | H27: =IF(B27=0,0,(B27-G27)/B27) -> 0.20363636

Sheet Test Data & Setup
A1: Item | B1: Details / what to prepare
A2: Environment | B2: Test URL (staging/prod): ______ Build/commit: ______ Date: ______
A3: Browsers / devices | B3: Chrome, Edge, Firefox, Safari; Android Chrome; iOS Safari; widths 320 / 375 / 768 / 1280 / 1920
A4: Account A | B4: Verified user with password (for login success)
A5: Account B | B5: Brand-new email you can read (register, sign-in link, complete profile)
A6: Account C | B6: Owner account with a business and shared documents: unpaid, partly paid, fully paid, cancelled, quotation, challan
A7: Account D | B7: Invite emails: valid, expired, revoked, already accepted, wrong-email
A8: Partner data | B8: Approved partner with referral code; one pending; one not publicly listed
A9: Share links | B9: Valid, revoked, garbage token; invoice with logo / bank / UPI / free qty / discount
A10: Invalid inputs | B10: Emails: abc, a@b, ' a@b.com '; Phones: 12345, abc, +91 98765-43210; Websites: abc, yourfirm.com; Payloads: ' OR 1=1 --, <script>alert(1)</script>, emoji, Hindi/Gujarati text
A11: Inbox | B11: Mailbox access for sign-in links and contact/partner enquiries
A12: Bot check | B12: Turnstile test keys or ability to pass the challenge; also test with ad-blocker on
A13: Status legend | B13: Pass = matches expected; Fail = does not (log Defect ID); Blocked = cannot test; Skipped = not applicable; Not Run

Sheet Page Inventory
A1: Page | B1: URL | C1: Signed-out access? | D1: Notes
A2: Home | B2: / | C2: Yes | D2: Goes to app when signed in
A3: Log in | B3: /login | C3: Yes
A4: Register | B4: /register | C4: Yes | D4: ?ref= and ?invite=
A5: Sign-in link verify | B5: /auth/verify | C5: Yes | D5: ?token=&source=
A6: Complete profile | B6: /auth/complete-profile | C6: Needs session
A7: Plan selection | B7: /auth/plan-selection | C7: Needs session
A8: Verify email change | B8: /auth/verify-email-change | C8: Token link | D8: NOT covered in test cases - add after checking the email-change flow in Settings
A9: Invite | B9: /invite/:token | C9: Yes
A10: Shared document | B10: /i/:token | C10: Yes | D10: No sign-in needed
A11: Pricing | B11: /pricing | C11: Yes
A12: Features index + 27 pages | B12: /features/... | C12: Yes
A13: Solutions index + 12 pages | B13: /solutions/... | C13: Yes
A14: About | B14: /about | C14: Yes
A15: Contact | B15: /contact | C15: Yes
A16: Partners | B16: /partners | C16: Yes
A17: Partner apply | B17: /partners/apply | C17: Yes
A18: Find a partner | B18: /find-a-partner | C18: Yes
A19: Partner portal | B19: /partner-portal | C19: Needs session
A20: Security | B20: /security | C20: Yes
A21: Report vulnerability | B21: /security/report | C21: Yes
A22: Privacy | B22: /privacy | C22: Yes
... A27: Widgets gallery | B27: /widgets | C27: Yes
